<?xml version="1.0" ?>
<!--
  Ignition Gazebo differential drive plugin demo

  Try sending commands:

    ign topic -t "/model/vehicle_blue/cmd_vel" -m ignition.msgs.Twist -p "linear: {x: 0.5}, angular: {z: 0.05}"

    ign topic -t "/model/vehicle_green/cmd_vel" -m ignition.msgs.Twist -p "linear: {x: 1.0}, angular: {z: -0.1}"

  Listen to odometry:

    ign topic -e -t /model/vehicle_blue/odometry

    ign topic -e -t /model/vehicle_green/odometry

-->
<sdf version="1.7">
  <world name="diff_drive">

    <physics name="1ms" type="ignored">
      <max_step_size>0.001</max_step_size>
      <real_time_factor>1.0</real_time_factor>
    </physics>
    <plugin
            filename="ignition-gazebo-physics-system"
            name="ignition::gazebo::systems::Physics">
    </plugin>
    <plugin
            filename="ignition-gazebo-user-commands-system"
            name="ignition::gazebo::systems::UserCommands">
    </plugin>
    <plugin
            filename="ignition-gazebo-scene-broadcaster-system"
            name="ignition::gazebo::systems::SceneBroadcaster">
    </plugin>
    <plugin filename="ignition-gazebo-imu-system"
            name="ignition::gazebo::systems::Imu">
    </plugin>
    <plugin
            filename="libignition-gazebo-sensors-system.so"
            name="ignition::gazebo::systems::Sensors">
      <render_engine>ogre2</render_engine>
    </plugin>

    <gui fullscreen="1">

      <!-- 3D scene -->
      <plugin filename="GzScene3D" name="3D View">
        <ignition-gui>
          <title>3D View</title>
          <property type="bool" key="showTitleBar">false</property>
          <property type="string" key="state">docked</property>
        </ignition-gui>

        <engine>ogre2</engine>
        <scene>scene</scene>
        <ambient_light>0.4 0.4 0.4</ambient_light>
        <background_color>0.8 0.8 0.8</background_color>
        <camera_pose>-1 0 1 0 0.5 0</camera_pose>
      </plugin>

      <!-- World control -->
      <plugin filename="WorldControl" name="World control">
        <ignition-gui>
          <title>World control</title>
          <property type="bool" key="showTitleBar">false</property>
          <property type="bool" key="resizable">false</property>
          <property type="double" key="height">72</property>
          <property type="double" key="width">121</property>
          <property type="double" key="z">1</property>

          <property type="string" key="state">floating</property>
          <anchors target="3D View">
            <line own="left" target="left"/>
            <line own="bottom" target="bottom"/>
          </anchors>
        </ignition-gui>

        <play_pause>true</play_pause>
        <step>true</step>
        <start_paused>true</start_paused>
        <service>/world/diff_drive/control</service>
        <stats_topic>/world/diff_drive/stats</stats_topic>
      </plugin>

      <!-- World statistics -->
      <plugin filename="WorldStats" name="World stats">
        <ignition-gui>
          <title>World stats</title>
          <property type="bool" key="showTitleBar">false</property>
          <property type="bool" key="resizable">false</property>
          <property type="double" key="height">110</property>
          <property type="double" key="width">290</property>
          <property type="double" key="z">1</property>

          <property type="string" key="state">floating</property>
          <anchors target="3D View">
            <line own="right" target="right"/>
            <line own="bottom" target="bottom"/>
          </anchors>
        </ignition-gui>

        <sim_time>true</sim_time>
        <real_time>true</real_time>
        <real_time_factor>true</real_time_factor>
        <iterations>true</iterations>
        <topic>/world/diff_drive/stats</topic>

      </plugin>

      <!-- Entity tree -->
      <plugin filename="EntityTree" name="Entity tree">
      </plugin>

    </gui>

    <light type="directional" name="sun">
      <cast_shadows>true</cast_shadows>
      <pose>0 0 10 0 0 0</pose>
      <diffuse>1 1 1 1</diffuse>
      <specular>0.5 0.5 0.5 1</specular>
      <attenuation>
        <range>1000</range>
        <constant>0.9</constant>
        <linear>0.01</linear>
        <quadratic>0.001</quadratic>
      </attenuation>
      <direction>-0.5 0.1 -0.9</direction>
    </light>

    <model name="ground_plane">
      <pose relative_to='world'>0 0 0 0 0 0</pose>

      <static>true</static>
      <link name="link">
        <collision name="collision">
          <geometry>
            <plane>
              <normal>0 0 1</normal>
              <size>100 100</size>
            </plane>
          </geometry>
        </collision>
        <visual name="visual">
          <geometry>
            <plane>
              <normal>0 0 1</normal>
              <size>100 100</size>
            </plane>
          </geometry>
          <material>
            <ambient>0.8 0.8 0.8 1</ambient>
            <diffuse>0.8 0.8 0.8 1</diffuse>
            <specular>0.8 0.8 0.8 1</specular>
          </material>
        </visual>
      </link>
    </model>

    <model name='duckiebot' canonical_link='chassis'>
      <pose relative_to='world'>0.0 0.0 0.0325 0 0 0</pose>

      <frame name="lidar_frame" attached_to='chassis'>
        <pose>-0.04 0 0.05 0 0 0</pose>
      </frame>

      <link name='chassis'>
        <pose relative_to='__model__'>-0.0525 0.0 0.0375 0 0 0</pose>
        <inertial>
          <mass>0.857</mass>
          <inertia>
            <ixx>0.0011712</ixx>
            <ixy>0</ixy>
            <ixz>0</ixz>
            <iyy>0.0022157</iyy>
            <iyz>0</iyz>
            <izz>0.0019586</izz>
          </inertia>
        </inertial>
        <visual name='visual'>
          <geometry>
            <box>
              <size>0.145 0.08 0.10</size>
            </box>
          </geometry>
          <material>
            <ambient>0.0 0.0 1.0 1</ambient>
            <diffuse>0.0 0.0 1.0 1</diffuse>
            <specular>0.0 0.0 1.0 1</specular>
          </material>
        </visual>
        <collision name='collision'>
          <geometry>
            <box>
              <size>0.145 0.08 0.10</size>
            </box>
          </geometry>
        </collision>
        <sensor name="imu_sensor" type="imu">
          <always_on>1</always_on>
          <update_rate>1</update_rate>
          <visualize>true</visualize>
          <topic>imu</topic>
        </sensor>
      </link>

      <link name='lidar'>
        <pose relative_to='lidar_frame'>0 0 0.015 0 0 0</pose>
        <inertial>
          <mass>0.1</mass>
          <inertia>
            <ixx>0.00003</ixx>
            <ixy>0</ixy>
            <ixz>0</ixz>
            <iyy>0.00003</iyy>
            <iyz>0</iyz>
            <izz>0.000045</izz>
          </inertia>
        </inertial>
        <visual name='visual'>
          <geometry>
            <cylinder>
              <radius>0.03</radius>
              <length>0.03</length>
            </cylinder>
          </geometry>
          <material>
            <ambient>0.0 0.0 1.0 1</ambient>
            <diffuse>0.0 0.0 1.0 1</diffuse>
            <specular>0.0 0.0 1.0 1</specular>
          </material>
        </visual>
        <collision name='collision'>
          <geometry>
            <cylinder>
              <radius>0.03</radius>
              <length>0.03</length>
            </cylinder>
          </geometry>
        </collision>
        <sensor name='gpu_lidar' type='gpu_lidar'>"
          <pose relative_to='lidar_frame'>0 0 0 0 0 0</pose>
          <topic>lidar</topic>
          <update_rate>10</update_rate>
          <ray>
            <scan>
              <horizontal>
                <samples>640</samples>
                <resolution>1</resolution>
                <min_angle>-1.396263</min_angle>
                <max_angle>1.396263</max_angle>
              </horizontal>
              <vertical>
                <samples>1</samples>
                <resolution>0.01</resolution>
                <min_angle>0</min_angle>
                <max_angle>0</max_angle>
              </vertical>
            </scan>
            <range>
              <min>0.08</min>
              <max>10.0</max>
              <resolution>0.01</resolution>
            </range>
          </ray>
          <always_on>1</always_on>
          <visualize>true</visualize>
        </sensor>
      </link>

      <link name='left_wheel'>
        <pose relative_to="__model__">0.0 0.0525 0.0 -1.5707 0 0</pose>
        <inertial>
          <mass>0.0326</mass>
          <inertia>
            <ixx>0.00003613</ixx>
            <ixy>0</ixy>
            <ixz>0</ixz>
            <iyy>0.00003613</iyy>
            <iyz>0</iyz>
            <izz>0.00006887</izz>
          </inertia>
        </inertial>
        <visual name='visual'>
          <geometry>
            <cylinder>
              <radius>0.0325</radius>
              <length>0.025</length>
            </cylinder>
          </geometry>
          <material>
            <ambient>0.2 0.2 0.2 1</ambient>
            <diffuse>0.2 0.2 0.2 1</diffuse>
            <specular>0.2 0.2 0.2 1</specular>
          </material>
        </visual>
        <collision name='collision'>
          <geometry>
            <cylinder>
              <radius>0.0325</radius>
              <length>0.025</length>
            </cylinder>
          </geometry>
        </collision>
      </link>

      <link name='right_wheel'>
        <pose relative_to="__model__">0.0 -0.0525 0.0 -1.5707 0 0</pose>
        <inertial>
          <mass>0.0326</mass>
          <inertia>
            <ixx>0.00003613</ixx>
            <ixy>0</ixy>
            <ixz>0</ixz>
            <iyy>0.00003613</iyy>
            <iyz>0</iyz>
            <izz>0.00006887</izz>
          </inertia>
        </inertial>
        <visual name='visual'>
          <geometry>
            <cylinder>
              <radius>0.0325</radius>
              <length>0.025</length>
            </cylinder>
          </geometry>
          <material>
            <ambient>0.2 0.2 0.2 1</ambient>
            <diffuse>0.2 0.2 0.2 1</diffuse>
            <specular>0.2 0.2 0.2 1</specular>
          </material>
        </visual>
        <collision name='collision'>
          <geometry>
            <cylinder>
              <radius>0.0325</radius>
              <length>0.025</length>
            </cylinder>
          </geometry>
        </collision>
      </link>

      <link name='caster'>
        <pose relative_to="chassis">-0.0375 0 -0.06 0 0 0</pose>
        <inertial>
          <mass>0.01</mass>
          <inertia>
            <ixx>0.0000004</ixx>
            <ixy>0</ixy>
            <ixz>0</ixz>
            <iyy>0.0000004</iyy>
            <iyz>0</iyz>
            <izz>0.0000004</izz>
          </inertia>
        </inertial>
        <visual name='visual'>
          <geometry>
            <sphere>
              <radius>0.01</radius>
            </sphere>
          </geometry>
          <material>
            <ambient>0.2 0.2 0.2 1</ambient>
            <diffuse>0.2 0.2 0.2 1</diffuse>
            <specular>0.2 0.2 0.2 1</specular>
          </material>
        </visual>
        <collision name='collision'>
          <geometry>
            <sphere>
              <radius>0.01</radius>
            </sphere>
          </geometry>
        </collision>
      </link>

      <joint name='lidar_joint' type='revolute'>
        <parent>chassis</parent>
        <child>lidar</child>
        <axis>
          <xyz>0 1 0</xyz>
          <limit>
            <lower>0</lower>
            <upper>0</upper>
          </limit>
        </axis>
      </joint>

      <joint name='left_wheel_joint' type='revolute'>
        <pose relative_to='left_wheel'/>
        <parent>chassis</parent>
        <child>left_wheel</child>
        <axis>
          <xyz expressed_in='__model__'>0 1 0</xyz>
          <limit>
            <lower>-1.79769e+308</lower>
            <upper>1.79769e+308</upper>
          </limit>
        </axis>
      </joint>

      <joint name='right_wheel_joint' type='revolute'>
        <pose relative_to='right_wheel'/>
        <parent>chassis</parent>
        <child>right_wheel</child>
        <axis>
          <xyz expressed_in='__model__'>0 1 0</xyz>
          <limit>
            <lower>-1.79769e+308</lower>
            <upper>1.79769e+308</upper>
          </limit>
        </axis>
      </joint>

      <joint name='caster_wheel' type='ball'>
        <parent>chassis</parent>
        <child>caster</child>
      </joint>

      <plugin
              filename="libignition-gazebo-diff-drive-system.so"
              name="ignition::gazebo::systems::DiffDrive">
        <left_joint>left_wheel_joint</left_joint>
        <right_joint>right_wheel_joint</right_joint>
        <wheel_separation>0.105</wheel_separation>
        <wheel_radius>0.0325</wheel_radius>
        <odom_publish_frequency>1</odom_publish_frequency>
        <topic>cmd_vel</topic>
      </plugin>

    </model>

  </world>
</sdf>
